2023-01-26T15:41:17,379 Using pip 22.3.1 from c:\users\rabot\.pyenv\pyenv-win\versions\3.7.4\lib\site-packages\pip (python 3.7)
2023-01-26T15:41:17,385 Non-user install because site-packages writeable
2023-01-26T15:41:17,863 Created temporary directory: C:\Users\rabot\AppData\Local\Temp\pip-build-tracker-4b7itnlh
2023-01-26T15:41:17,864 Initialized build tracking at C:\Users\rabot\AppData\Local\Temp\pip-build-tracker-4b7itnlh
2023-01-26T15:41:17,864 Created build tracker: C:\Users\rabot\AppData\Local\Temp\pip-build-tracker-4b7itnlh
2023-01-26T15:41:17,864 Entered build tracker: C:\Users\rabot\AppData\Local\Temp\pip-build-tracker-4b7itnlh
2023-01-26T15:41:17,865 Created temporary directory: C:\Users\rabot\AppData\Local\Temp\pip-install-wafxgyo9
2023-01-26T15:41:17,868 Created temporary directory: C:\Users\rabot\AppData\Local\Temp\pip-ephem-wheel-cache-pta890gq
2023-01-26T15:41:17,886 1 location(s) to search for versions of cat:
2023-01-26T15:41:17,886 * https://pypi.org/simple/cat/
2023-01-26T15:41:17,886 Fetching project page and analyzing links: https://pypi.org/simple/cat/
2023-01-26T15:41:17,886 Getting page https://pypi.org/simple/cat/
2023-01-26T15:41:17,887 Found index url https://pypi.org/simple
2023-01-26T15:41:18,391 Fetched page https://pypi.org/simple/cat/ as application/vnd.pypi.simple.v1+json
2023-01-26T15:41:18,392 Skipping link: not a file: https://pypi.org/simple/cat/
2023-01-26T15:41:18,393 Given no hashes to check 0 links for project 'cat': discarding no candidates
2023-01-26T15:41:18,393 ERROR: Could not find a version that satisfies the requirement cat (from versions: none)
2023-01-26T15:41:18,397 ERROR: No matching distribution found for cat
2023-01-26T15:41:18,398 Exception information:
2023-01-26T15:41:18,398 Traceback (most recent call last):
2023-01-26T15:41:18,398   File "c:\users\rabot\.pyenv\pyenv-win\versions\3.7.4\lib\site-packages\pip\_vendor\resolvelib\resolvers.py", line 348, in resolve
2023-01-26T15:41:18,398     self._add_to_criteria(self.state.criteria, r, parent=None)
2023-01-26T15:41:18,398   File "c:\users\rabot\.pyenv\pyenv-win\versions\3.7.4\lib\site-packages\pip\_vendor\resolvelib\resolvers.py", line 173, in _add_to_criteria
2023-01-26T15:41:18,398     raise RequirementsConflicted(criterion)
2023-01-26T15:41:18,398 pip._vendor.resolvelib.resolvers.RequirementsConflicted: Requirements conflict: SpecifierRequirement('cat')
2023-01-26T15:41:18,398 
2023-01-26T15:41:18,398 During handling of the above exception, another exception occurred:
2023-01-26T15:41:18,398 
2023-01-26T15:41:18,398 Traceback (most recent call last):
2023-01-26T15:41:18,398   File "c:\users\rabot\.pyenv\pyenv-win\versions\3.7.4\lib\site-packages\pip\_internal\resolution\resolvelib\resolver.py", line 93, in resolve
2023-01-26T15:41:18,398     collected.requirements, max_rounds=try_to_avoid_resolution_too_deep
2023-01-26T15:41:18,398   File "c:\users\rabot\.pyenv\pyenv-win\versions\3.7.4\lib\site-packages\pip\_vendor\resolvelib\resolvers.py", line 481, in resolve
2023-01-26T15:41:18,398     state = resolution.resolve(requirements, max_rounds=max_rounds)
2023-01-26T15:41:18,398   File "c:\users\rabot\.pyenv\pyenv-win\versions\3.7.4\lib\site-packages\pip\_vendor\resolvelib\resolvers.py", line 350, in resolve
2023-01-26T15:41:18,398     raise ResolutionImpossible(e.criterion.information)
2023-01-26T15:41:18,398 pip._vendor.resolvelib.resolvers.ResolutionImpossible: [RequirementInformation(requirement=SpecifierRequirement('cat'), parent=None)]
2023-01-26T15:41:18,398 
2023-01-26T15:41:18,398 The above exception was the direct cause of the following exception:
2023-01-26T15:41:18,398 
2023-01-26T15:41:18,398 Traceback (most recent call last):
2023-01-26T15:41:18,398   File "c:\users\rabot\.pyenv\pyenv-win\versions\3.7.4\lib\site-packages\pip\_internal\cli\base_command.py", line 160, in exc_logging_wrapper
2023-01-26T15:41:18,398     status = run_func(*args)
2023-01-26T15:41:18,398   File "c:\users\rabot\.pyenv\pyenv-win\versions\3.7.4\lib\site-packages\pip\_internal\cli\req_command.py", line 247, in wrapper
2023-01-26T15:41:18,398     return func(self, options, args)
2023-01-26T15:41:18,398   File "c:\users\rabot\.pyenv\pyenv-win\versions\3.7.4\lib\site-packages\pip\_internal\commands\install.py", line 401, in run
2023-01-26T15:41:18,398     reqs, check_supported_wheels=not options.target_dir
2023-01-26T15:41:18,398   File "c:\users\rabot\.pyenv\pyenv-win\versions\3.7.4\lib\site-packages\pip\_internal\resolution\resolvelib\resolver.py", line 101, in resolve
2023-01-26T15:41:18,398     raise error from e
2023-01-26T15:41:18,398 pip._internal.exceptions.DistributionNotFound: No matching distribution found for cat
2023-01-26T15:41:18,678 Remote version of pip: 22.3.1
2023-01-26T15:41:18,678 Local version of pip:  22.3.1
2023-01-26T15:41:18,679 Was pip installed by pip? True
2023-01-26T15:41:18,680 Removed build tracker: 'C:\\Users\\rabot\\AppData\\Local\\Temp\\pip-build-tracker-4b7itnlh'
