2023-01-26T15:40:56,711 Using pip 22.3.1 from c:\users\rabot\.pyenv\pyenv-win\versions\3.7.4\lib\site-packages\pip (python 3.7)
2023-01-26T15:40:56,717 Non-user install because site-packages writeable
2023-01-26T15:40:57,766 Created temporary directory: C:\Users\rabot\AppData\Local\Temp\pip-build-tracker-inhqgi0r
2023-01-26T15:40:57,767 Initialized build tracking at C:\Users\rabot\AppData\Local\Temp\pip-build-tracker-inhqgi0r
2023-01-26T15:40:57,767 Created build tracker: C:\Users\rabot\AppData\Local\Temp\pip-build-tracker-inhqgi0r
2023-01-26T15:40:57,767 Entered build tracker: C:\Users\rabot\AppData\Local\Temp\pip-build-tracker-inhqgi0r
2023-01-26T15:40:57,768 Created temporary directory: C:\Users\rabot\AppData\Local\Temp\pip-install-131ci2zl
2023-01-26T15:40:57,776 Created temporary directory: C:\Users\rabot\AppData\Local\Temp\pip-ephem-wheel-cache-qrc0wf9x
2023-01-26T15:40:57,811 1 location(s) to search for versions of requirements-txt:
2023-01-26T15:40:57,811 * https://pypi.org/simple/requirements-txt/
2023-01-26T15:40:57,811 Fetching project page and analyzing links: https://pypi.org/simple/requirements-txt/
2023-01-26T15:40:57,811 Getting page https://pypi.org/simple/requirements-txt/
2023-01-26T15:40:57,812 Found index url https://pypi.org/simple
2023-01-26T15:40:58,152 Could not fetch URL https://pypi.org/simple/requirements-txt/: 404 Client Error: Not Found for url: https://pypi.org/simple/requirements-txt/ - skipping
2023-01-26T15:40:58,152 Skipping link: not a file: https://pypi.org/simple/requirements-txt/
2023-01-26T15:40:58,152 Given no hashes to check 0 links for project 'requirements-txt': discarding no candidates
2023-01-26T15:40:58,153 ERROR: Could not find a version that satisfies the requirement requirements.txt (from versions: none)
2023-01-26T15:40:58,163 HINT: You are attempting to install a package literally named "requirements.txt" (which cannot exist). Consider using the '-r' flag to install the packages listed in requirements.txt
2023-01-26T15:40:58,164 ERROR: No matching distribution found for requirements.txt
2023-01-26T15:40:58,166 Exception information:
2023-01-26T15:40:58,166 Traceback (most recent call last):
2023-01-26T15:40:58,166   File "c:\users\rabot\.pyenv\pyenv-win\versions\3.7.4\lib\site-packages\pip\_vendor\resolvelib\resolvers.py", line 348, in resolve
2023-01-26T15:40:58,166     self._add_to_criteria(self.state.criteria, r, parent=None)
2023-01-26T15:40:58,166   File "c:\users\rabot\.pyenv\pyenv-win\versions\3.7.4\lib\site-packages\pip\_vendor\resolvelib\resolvers.py", line 173, in _add_to_criteria
2023-01-26T15:40:58,166     raise RequirementsConflicted(criterion)
2023-01-26T15:40:58,166 pip._vendor.resolvelib.resolvers.RequirementsConflicted: Requirements conflict: SpecifierRequirement('requirements.txt')
2023-01-26T15:40:58,166 
2023-01-26T15:40:58,166 During handling of the above exception, another exception occurred:
2023-01-26T15:40:58,166 
2023-01-26T15:40:58,166 Traceback (most recent call last):
2023-01-26T15:40:58,166   File "c:\users\rabot\.pyenv\pyenv-win\versions\3.7.4\lib\site-packages\pip\_internal\resolution\resolvelib\resolver.py", line 93, in resolve
2023-01-26T15:40:58,166     collected.requirements, max_rounds=try_to_avoid_resolution_too_deep
2023-01-26T15:40:58,166   File "c:\users\rabot\.pyenv\pyenv-win\versions\3.7.4\lib\site-packages\pip\_vendor\resolvelib\resolvers.py", line 481, in resolve
2023-01-26T15:40:58,166     state = resolution.resolve(requirements, max_rounds=max_rounds)
2023-01-26T15:40:58,166   File "c:\users\rabot\.pyenv\pyenv-win\versions\3.7.4\lib\site-packages\pip\_vendor\resolvelib\resolvers.py", line 350, in resolve
2023-01-26T15:40:58,166     raise ResolutionImpossible(e.criterion.information)
2023-01-26T15:40:58,166 pip._vendor.resolvelib.resolvers.ResolutionImpossible: [RequirementInformation(requirement=SpecifierRequirement('requirements.txt'), parent=None)]
2023-01-26T15:40:58,166 
2023-01-26T15:40:58,166 The above exception was the direct cause of the following exception:
2023-01-26T15:40:58,166 
2023-01-26T15:40:58,166 Traceback (most recent call last):
2023-01-26T15:40:58,166   File "c:\users\rabot\.pyenv\pyenv-win\versions\3.7.4\lib\site-packages\pip\_internal\cli\base_command.py", line 160, in exc_logging_wrapper
2023-01-26T15:40:58,166     status = run_func(*args)
2023-01-26T15:40:58,166   File "c:\users\rabot\.pyenv\pyenv-win\versions\3.7.4\lib\site-packages\pip\_internal\cli\req_command.py", line 247, in wrapper
2023-01-26T15:40:58,166     return func(self, options, args)
2023-01-26T15:40:58,166   File "c:\users\rabot\.pyenv\pyenv-win\versions\3.7.4\lib\site-packages\pip\_internal\commands\install.py", line 401, in run
2023-01-26T15:40:58,166     reqs, check_supported_wheels=not options.target_dir
2023-01-26T15:40:58,166   File "c:\users\rabot\.pyenv\pyenv-win\versions\3.7.4\lib\site-packages\pip\_internal\resolution\resolvelib\resolver.py", line 101, in resolve
2023-01-26T15:40:58,166     raise error from e
2023-01-26T15:40:58,166 pip._internal.exceptions.DistributionNotFound: No matching distribution found for requirements.txt
2023-01-26T15:40:58,617 Remote version of pip: 22.3.1
2023-01-26T15:40:58,618 Local version of pip:  22.3.1
2023-01-26T15:40:58,620 Was pip installed by pip? True
2023-01-26T15:40:58,620 Removed build tracker: 'C:\\Users\\rabot\\AppData\\Local\\Temp\\pip-build-tracker-inhqgi0r'
